2020/09/21 18:29:00 - INFO - 44 - __init__ - ********开始 今日头条极速版 的任务********
2020/09/21 18:29:08 - INFO - 19 - jin_ri_tou_tiao - 开始签到
2020/09/21 18:29:17 - INFO - 180 - jin_ri_tou_tiao - 获取今日金币数量
2020/09/21 18:29:25 - INFO - 189 - jin_ri_tou_tiao - 今日已经获取金币 100
2020/09/21 18:29:25 - INFO - 56 - jin_ri_tou_tiao - 开始阅读文章
2020/09/21 18:29:49 - CRITICAL - 114 - __init__ - 出严重错误啦，以下是错误信息['//*[@resource-id="com.ss.android.article.lite:id/a4x"]/android.widget.LinearLayout[1]/android.widget.FrameLayout[last()]']
Traceback (most recent call last):
  File "D:\python_project\read_phone_project\app_jiao_ben\__init__.py", line 109, in recycle_main_do
    self.main_do(duration, target_coin, cash_out)
  File "D:\python_project\read_phone_project\app_jiao_ben\jin_ri_tou_tiao.py", line 209, in main_do
    self.read_issue(duration, target_coin)
  File "D:\python_project\read_phone_project\app_jiao_ben\jin_ri_tou_tiao.py", line 62, in read_issue
    if self.pp.xpath('//*[@resource-id="com.ss.android.article.lite:id/a4x"]/android.widget.LinearLayout[1]/'
  File "C:\Users\jiaji\AppData\Local\Programs\Python\Python38\lib\site-packages\uiautomator2\xpath.py", line 518, in get
    raise XPathElementNotFoundError(self._xpath_list)
uiautomator2.exceptions.XPathElementNotFoundError: ['//*[@resource-id="com.ss.android.article.lite:id/a4x"]/android.widget.LinearLayout[1]/android.widget.FrameLayout[last()]']
2020/09/21 18:29:57 - INFO - 44 - __init__ - ********开始 今日头条极速版 的任务********
2020/09/21 18:30:04 - INFO - 19 - jin_ri_tou_tiao - 开始签到
2020/09/21 18:30:13 - INFO - 180 - jin_ri_tou_tiao - 获取今日金币数量
2020/09/21 18:30:19 - INFO - 189 - jin_ri_tou_tiao - 今日已经获取金币 100
2020/09/21 18:30:19 - INFO - 56 - jin_ri_tou_tiao - 开始阅读文章
2020/09/21 18:30:42 - CRITICAL - 114 - __init__ - 出严重错误啦，以下是错误信息['//*[@resource-id="com.ss.android.article.lite:id/a4x"]/android.widget.LinearLayout[1]/android.widget.FrameLayout[last()]']
Traceback (most recent call last):
  File "D:\python_project\read_phone_project\app_jiao_ben\__init__.py", line 109, in recycle_main_do
    self.main_do(duration, target_coin, cash_out)
  File "D:\python_project\read_phone_project\app_jiao_ben\jin_ri_tou_tiao.py", line 209, in main_do
    self.read_issue(duration, target_coin)
  File "D:\python_project\read_phone_project\app_jiao_ben\jin_ri_tou_tiao.py", line 62, in read_issue
    if self.pp.xpath('//*[@resource-id="com.ss.android.article.lite:id/a4x"]/android.widget.LinearLayout[1]/'
  File "C:\Users\jiaji\AppData\Local\Programs\Python\Python38\lib\site-packages\uiautomator2\xpath.py", line 518, in get
    raise XPathElementNotFoundError(self._xpath_list)
uiautomator2.exceptions.XPathElementNotFoundError: ['//*[@resource-id="com.ss.android.article.lite:id/a4x"]/android.widget.LinearLayout[1]/android.widget.FrameLayout[last()]']
2020/09/21 18:30:51 - INFO - 44 - __init__ - ********开始 今日头条极速版 的任务********
2020/09/21 18:31:00 - INFO - 19 - jin_ri_tou_tiao - 开始签到
2020/09/21 20:12:01 - INFO - 44 - __init__ - ********开始 今日头条极速版 的任务********
2020/09/21 20:12:10 - INFO - 19 - jin_ri_tou_tiao - 开始签到
2020/09/21 20:12:19 - INFO - 180 - jin_ri_tou_tiao - 获取今日金币数量
2020/09/21 20:12:27 - INFO - 189 - jin_ri_tou_tiao - 今日已经获取金币 100
2020/09/21 20:12:27 - INFO - 56 - jin_ri_tou_tiao - 开始阅读文章
2020/09/21 20:12:32 - INFO - 28 - jin_ri_tou_tiao - 开始调整栏目
2020/09/21 20:15:44 - INFO - 44 - __init__ - ********开始 今日头条极速版 的任务********
2020/09/21 20:15:48 - INFO - 19 - jin_ri_tou_tiao - 开始签到
2020/09/21 20:15:57 - INFO - 180 - jin_ri_tou_tiao - 获取今日金币数量
2020/09/21 20:16:05 - INFO - 189 - jin_ri_tou_tiao - 今日已经获取金币 100
2020/09/21 20:16:05 - INFO - 56 - jin_ri_tou_tiao - 开始阅读文章
2020/09/21 20:16:11 - INFO - 28 - jin_ri_tou_tiao - 开始调整栏目
2020/09/21 20:27:55 - INFO - 44 - __init__ - ********开始 今日头条极速版 的任务********
2020/09/21 20:28:02 - INFO - 19 - jin_ri_tou_tiao - 开始签到
2020/09/21 20:28:11 - INFO - 180 - jin_ri_tou_tiao - 获取今日金币数量
2020/09/21 20:28:16 - INFO - 189 - jin_ri_tou_tiao - 今日已经获取金币 1979
2020/09/21 20:28:16 - INFO - 56 - jin_ri_tou_tiao - 开始阅读文章
2020/09/21 20:31:44 - INFO - 44 - __init__ - ********开始 今日头条极速版 的任务********
2020/09/21 20:31:51 - INFO - 19 - jin_ri_tou_tiao - 开始签到
2020/09/21 20:32:02 - INFO - 160 - jin_ri_tou_tiao - 获取今日金币数量
2020/09/21 20:32:08 - INFO - 169 - jin_ri_tou_tiao - 今日已经获取金币 1979
2020/09/21 20:32:08 - INFO - 56 - jin_ri_tou_tiao - 开始阅读文章
2020/09/21 20:37:51 - INFO - 44 - __init__ - ********开始 今日头条极速版 的任务********
2020/09/21 20:37:59 - INFO - 19 - jin_ri_tou_tiao - 开始签到
2020/09/21 20:38:08 - INFO - 164 - jin_ri_tou_tiao - 获取今日金币数量
2020/09/21 20:38:17 - INFO - 173 - jin_ri_tou_tiao - 今日已经获取金币 2070
2020/09/21 20:38:17 - INFO - 56 - jin_ri_tou_tiao - 开始阅读文章
2020/09/21 20:41:50 - CRITICAL - 114 - __init__ - 出严重错误啦，以下是错误信息('Connection aborted.', RemoteDisconnected('Remote end closed connection without response'))
Traceback (most recent call last):
  File "C:\Users\jiaji\AppData\Local\Programs\Python\Python38\lib\site-packages\urllib3\connectionpool.py", line 670, in urlopen
    httplib_response = self._make_request(
  File "C:\Users\jiaji\AppData\Local\Programs\Python\Python38\lib\site-packages\urllib3\connectionpool.py", line 426, in _make_request
    six.raise_from(e, None)
  File "<string>", line 3, in raise_from
  File "C:\Users\jiaji\AppData\Local\Programs\Python\Python38\lib\site-packages\urllib3\connectionpool.py", line 421, in _make_request
    httplib_response = conn.getresponse()
  File "C:\Users\jiaji\AppData\Local\Programs\Python\Python38\lib\http\client.py", line 1347, in getresponse
    response.begin()
  File "C:\Users\jiaji\AppData\Local\Programs\Python\Python38\lib\http\client.py", line 307, in begin
    version, status, reason = self._read_status()
  File "C:\Users\jiaji\AppData\Local\Programs\Python\Python38\lib\http\client.py", line 276, in _read_status
    raise RemoteDisconnected("Remote end closed connection without"
http.client.RemoteDisconnected: Remote end closed connection without response

During handling of the above exception, another exception occurred:

Traceback (most recent call last):
  File "C:\Users\jiaji\AppData\Local\Programs\Python\Python38\lib\site-packages\requests\adapters.py", line 439, in send
    resp = conn.urlopen(
  File "C:\Users\jiaji\AppData\Local\Programs\Python\Python38\lib\site-packages\urllib3\connectionpool.py", line 724, in urlopen
    retries = retries.increment(
  File "C:\Users\jiaji\AppData\Local\Programs\Python\Python38\lib\site-packages\urllib3\util\retry.py", line 403, in increment
    raise six.reraise(type(error), error, _stacktrace)
  File "C:\Users\jiaji\AppData\Local\Programs\Python\Python38\lib\site-packages\urllib3\packages\six.py", line 734, in reraise
    raise value.with_traceback(tb)
  File "C:\Users\jiaji\AppData\Local\Programs\Python\Python38\lib\site-packages\urllib3\connectionpool.py", line 670, in urlopen
    httplib_response = self._make_request(
  File "C:\Users\jiaji\AppData\Local\Programs\Python\Python38\lib\site-packages\urllib3\connectionpool.py", line 426, in _make_request
    six.raise_from(e, None)
  File "<string>", line 3, in raise_from
  File "C:\Users\jiaji\AppData\Local\Programs\Python\Python38\lib\site-packages\urllib3\connectionpool.py", line 421, in _make_request
    httplib_response = conn.getresponse()
  File "C:\Users\jiaji\AppData\Local\Programs\Python\Python38\lib\http\client.py", line 1347, in getresponse
    response.begin()
  File "C:\Users\jiaji\AppData\Local\Programs\Python\Python38\lib\http\client.py", line 307, in begin
    version, status, reason = self._read_status()
  File "C:\Users\jiaji\AppData\Local\Programs\Python\Python38\lib\http\client.py", line 276, in _read_status
    raise RemoteDisconnected("Remote end closed connection without"
urllib3.exceptions.ProtocolError: ('Connection aborted.', RemoteDisconnected('Remote end closed connection without response'))

During handling of the above exception, another exception occurred:

Traceback (most recent call last):
  File "D:\python_project\read_phone_project\app_jiao_ben\__init__.py", line 109, in recycle_main_do
    self.main_do(duration, target_coin, cash_out)
  File "D:\python_project\read_phone_project\app_jiao_ben\jin_ri_tou_tiao.py", line 193, in main_do
    self.read_issue(duration, target_coin)
  File "D:\python_project\read_phone_project\app_jiao_ben\jin_ri_tou_tiao.py", line 117, in read_issue
    self.scroll_read_issue()
  File "D:\python_project\read_phone_project\app_jiao_ben\__init__.py", line 129, in scroll_read_issue
    self.pp.swipe(random.uniform(0.25, 0.7), random.uniform(0.15, 0.25),
  File "C:\Users\jiaji\AppData\Local\Programs\Python\Python38\lib\site-packages\uiautomator2\__init__.py", line 1035, in swipe
    return self.jsonrpc.swipe(fx, fy, tx, ty, steps)
  File "C:\Users\jiaji\AppData\Local\Programs\Python\Python38\lib\site-packages\uiautomator2\__init__.py", line 434, in __call__
    return self.server._jsonrpc_retry_call(self.method, params,
  File "C:\Users\jiaji\AppData\Local\Programs\Python\Python38\lib\site-packages\uiautomator2\__init__.py", line 441, in _jsonrpc_retry_call
    return self._jsonrpc_call(*args, **kwargs)
  File "C:\Users\jiaji\AppData\Local\Programs\Python\Python38\lib\site-packages\uiautomator2\__init__.py", line 470, in _jsonrpc_call
    res = self.http.post("/jsonrpc/0",
  File "C:\Users\jiaji\AppData\Local\Programs\Python\Python38\lib\site-packages\requests\sessions.py", line 578, in post
    return self.request('POST', url, data=data, json=json, **kwargs)
  File "C:\Users\jiaji\AppData\Local\Programs\Python\Python38\lib\site-packages\uiautomator2\__init__.py", line 188, in request
    return super().request(method, url, **kwargs)
  File "C:\Users\jiaji\AppData\Local\Programs\Python\Python38\lib\site-packages\uiautomator2\__init__.py", line 108, in request
    resp = super(TimeoutRequestsSession,
  File "C:\Users\jiaji\AppData\Local\Programs\Python\Python38\lib\site-packages\requests\sessions.py", line 530, in request
    resp = self.send(prep, **send_kwargs)
  File "C:\Users\jiaji\AppData\Local\Programs\Python\Python38\lib\site-packages\requests\sessions.py", line 643, in send
    r = adapter.send(request, **kwargs)
  File "C:\Users\jiaji\AppData\Local\Programs\Python\Python38\lib\site-packages\requests\adapters.py", line 498, in send
    raise ConnectionError(err, request=request)
requests.exceptions.ConnectionError: ('Connection aborted.', RemoteDisconnected('Remote end closed connection without response'))
2020/09/21 20:42:01 - INFO - 44 - __init__ - ********开始 今日头条极速版 的任务********
2020/09/21 20:42:08 - INFO - 19 - jin_ri_tou_tiao - 开始签到
2020/09/21 20:42:09 - CRITICAL - 114 - __init__ - 出严重错误啦，以下是错误信息('Connection aborted.', RemoteDisconnected('Remote end closed connection without response'))
Traceback (most recent call last):
  File "C:\Users\jiaji\AppData\Local\Programs\Python\Python38\lib\site-packages\urllib3\connectionpool.py", line 670, in urlopen
    httplib_response = self._make_request(
  File "C:\Users\jiaji\AppData\Local\Programs\Python\Python38\lib\site-packages\urllib3\connectionpool.py", line 426, in _make_request
    six.raise_from(e, None)
  File "<string>", line 3, in raise_from
  File "C:\Users\jiaji\AppData\Local\Programs\Python\Python38\lib\site-packages\urllib3\connectionpool.py", line 421, in _make_request
    httplib_response = conn.getresponse()
  File "C:\Users\jiaji\AppData\Local\Programs\Python\Python38\lib\http\client.py", line 1347, in getresponse
    response.begin()
  File "C:\Users\jiaji\AppData\Local\Programs\Python\Python38\lib\http\client.py", line 307, in begin
    version, status, reason = self._read_status()
  File "C:\Users\jiaji\AppData\Local\Programs\Python\Python38\lib\http\client.py", line 276, in _read_status
    raise RemoteDisconnected("Remote end closed connection without"
http.client.RemoteDisconnected: Remote end closed connection without response

During handling of the above exception, another exception occurred:

Traceback (most recent call last):
  File "C:\Users\jiaji\AppData\Local\Programs\Python\Python38\lib\site-packages\requests\adapters.py", line 439, in send
    resp = conn.urlopen(
  File "C:\Users\jiaji\AppData\Local\Programs\Python\Python38\lib\site-packages\urllib3\connectionpool.py", line 724, in urlopen
    retries = retries.increment(
  File "C:\Users\jiaji\AppData\Local\Programs\Python\Python38\lib\site-packages\urllib3\util\retry.py", line 403, in increment
    raise six.reraise(type(error), error, _stacktrace)
  File "C:\Users\jiaji\AppData\Local\Programs\Python\Python38\lib\site-packages\urllib3\packages\six.py", line 734, in reraise
    raise value.with_traceback(tb)
  File "C:\Users\jiaji\AppData\Local\Programs\Python\Python38\lib\site-packages\urllib3\connectionpool.py", line 670, in urlopen
    httplib_response = self._make_request(
  File "C:\Users\jiaji\AppData\Local\Programs\Python\Python38\lib\site-packages\urllib3\connectionpool.py", line 426, in _make_request
    six.raise_from(e, None)
  File "<string>", line 3, in raise_from
  File "C:\Users\jiaji\AppData\Local\Programs\Python\Python38\lib\site-packages\urllib3\connectionpool.py", line 421, in _make_request
    httplib_response = conn.getresponse()
  File "C:\Users\jiaji\AppData\Local\Programs\Python\Python38\lib\http\client.py", line 1347, in getresponse
    response.begin()
  File "C:\Users\jiaji\AppData\Local\Programs\Python\Python38\lib\http\client.py", line 307, in begin
    version, status, reason = self._read_status()
  File "C:\Users\jiaji\AppData\Local\Programs\Python\Python38\lib\http\client.py", line 276, in _read_status
    raise RemoteDisconnected("Remote end closed connection without"
urllib3.exceptions.ProtocolError: ('Connection aborted.', RemoteDisconnected('Remote end closed connection without response'))

During handling of the above exception, another exception occurred:

Traceback (most recent call last):
  File "D:\python_project\read_phone_project\app_jiao_ben\__init__.py", line 109, in recycle_main_do
    self.main_do(duration, target_coin, cash_out)
  File "D:\python_project\read_phone_project\app_jiao_ben\jin_ri_tou_tiao.py", line 190, in main_do
    self.sign_in()
  File "D:\python_project\read_phone_project\app_jiao_ben\jin_ri_tou_tiao.py", line 21, in sign_in
    self.pp(text='任务').click(offset=(random.random(), random.random()))
  File "C:\Users\jiaji\AppData\Local\Programs\Python\Python38\lib\site-packages\uiautomator2\_selector.py", line 150, in click
    self.must_wait(timeout=timeout)
  File "C:\Users\jiaji\AppData\Local\Programs\Python\Python38\lib\site-packages\uiautomator2\_selector.py", line 344, in must_wait
    if not self.wait(exists, timeout):
  File "C:\Users\jiaji\AppData\Local\Programs\Python\Python38\lib\site-packages\uiautomator2\_selector.py", line 314, in wait
    return self.jsonrpc.waitForExists(self.selector,
  File "C:\Users\jiaji\AppData\Local\Programs\Python\Python38\lib\site-packages\uiautomator2\__init__.py", line 434, in __call__
    return self.server._jsonrpc_retry_call(self.method, params,
  File "C:\Users\jiaji\AppData\Local\Programs\Python\Python38\lib\site-packages\uiautomator2\__init__.py", line 441, in _jsonrpc_retry_call
    return self._jsonrpc_call(*args, **kwargs)
  File "C:\Users\jiaji\AppData\Local\Programs\Python\Python38\lib\site-packages\uiautomator2\__init__.py", line 470, in _jsonrpc_call
    res = self.http.post("/jsonrpc/0",
  File "C:\Users\jiaji\AppData\Local\Programs\Python\Python38\lib\site-packages\requests\sessions.py", line 578, in post
    return self.request('POST', url, data=data, json=json, **kwargs)
  File "C:\Users\jiaji\AppData\Local\Programs\Python\Python38\lib\site-packages\uiautomator2\__init__.py", line 188, in request
    return super().request(method, url, **kwargs)
  File "C:\Users\jiaji\AppData\Local\Programs\Python\Python38\lib\site-packages\uiautomator2\__init__.py", line 108, in request
    resp = super(TimeoutRequestsSession,
  File "C:\Users\jiaji\AppData\Local\Programs\Python\Python38\lib\site-packages\requests\sessions.py", line 530, in request
    resp = self.send(prep, **send_kwargs)
  File "C:\Users\jiaji\AppData\Local\Programs\Python\Python38\lib\site-packages\requests\sessions.py", line 643, in send
    r = adapter.send(request, **kwargs)
  File "C:\Users\jiaji\AppData\Local\Programs\Python\Python38\lib\site-packages\requests\adapters.py", line 498, in send
    raise ConnectionError(err, request=request)
requests.exceptions.ConnectionError: ('Connection aborted.', RemoteDisconnected('Remote end closed connection without response'))
2020/09/21 20:42:15 - CRITICAL - 114 - __init__ - 出严重错误啦，以下是错误信息('Connection aborted.', RemoteDisconnected('Remote end closed connection without response'))
Traceback (most recent call last):
  File "C:\Users\jiaji\AppData\Local\Programs\Python\Python38\lib\site-packages\urllib3\connectionpool.py", line 670, in urlopen
    httplib_response = self._make_request(
  File "C:\Users\jiaji\AppData\Local\Programs\Python\Python38\lib\site-packages\urllib3\connectionpool.py", line 426, in _make_request
    six.raise_from(e, None)
  File "<string>", line 3, in raise_from
  File "C:\Users\jiaji\AppData\Local\Programs\Python\Python38\lib\site-packages\urllib3\connectionpool.py", line 421, in _make_request
    httplib_response = conn.getresponse()
  File "C:\Users\jiaji\AppData\Local\Programs\Python\Python38\lib\http\client.py", line 1347, in getresponse
    response.begin()
  File "C:\Users\jiaji\AppData\Local\Programs\Python\Python38\lib\http\client.py", line 307, in begin
    version, status, reason = self._read_status()
  File "C:\Users\jiaji\AppData\Local\Programs\Python\Python38\lib\http\client.py", line 276, in _read_status
    raise RemoteDisconnected("Remote end closed connection without"
http.client.RemoteDisconnected: Remote end closed connection without response

During handling of the above exception, another exception occurred:

Traceback (most recent call last):
  File "C:\Users\jiaji\AppData\Local\Programs\Python\Python38\lib\site-packages\requests\adapters.py", line 439, in send
    resp = conn.urlopen(
  File "C:\Users\jiaji\AppData\Local\Programs\Python\Python38\lib\site-packages\urllib3\connectionpool.py", line 724, in urlopen
    retries = retries.increment(
  File "C:\Users\jiaji\AppData\Local\Programs\Python\Python38\lib\site-packages\urllib3\util\retry.py", line 403, in increment
    raise six.reraise(type(error), error, _stacktrace)
  File "C:\Users\jiaji\AppData\Local\Programs\Python\Python38\lib\site-packages\urllib3\packages\six.py", line 734, in reraise
    raise value.with_traceback(tb)
  File "C:\Users\jiaji\AppData\Local\Programs\Python\Python38\lib\site-packages\urllib3\connectionpool.py", line 670, in urlopen
    httplib_response = self._make_request(
  File "C:\Users\jiaji\AppData\Local\Programs\Python\Python38\lib\site-packages\urllib3\connectionpool.py", line 426, in _make_request
    six.raise_from(e, None)
  File "<string>", line 3, in raise_from
  File "C:\Users\jiaji\AppData\Local\Programs\Python\Python38\lib\site-packages\urllib3\connectionpool.py", line 421, in _make_request
    httplib_response = conn.getresponse()
  File "C:\Users\jiaji\AppData\Local\Programs\Python\Python38\lib\http\client.py", line 1347, in getresponse
    response.begin()
  File "C:\Users\jiaji\AppData\Local\Programs\Python\Python38\lib\http\client.py", line 307, in begin
    version, status, reason = self._read_status()
  File "C:\Users\jiaji\AppData\Local\Programs\Python\Python38\lib\http\client.py", line 276, in _read_status
    raise RemoteDisconnected("Remote end closed connection without"
urllib3.exceptions.ProtocolError: ('Connection aborted.', RemoteDisconnected('Remote end closed connection without response'))

During handling of the above exception, another exception occurred:

Traceback (most recent call last):
  File "D:\python_project\read_phone_project\app_jiao_ben\__init__.py", line 109, in recycle_main_do
    self.main_do(duration, target_coin, cash_out)
  File "D:\python_project\read_phone_project\app_jiao_ben\jin_ri_tou_tiao.py", line 188, in main_do
    self.app_start('今日头条极速版')
  File "D:\python_project\read_phone_project\app_jiao_ben\__init__.py", line 34, in app_start
    app_list_running, app_install_list = self.pp.app_list_running(), self.pp.app_list()
  File "C:\Users\jiaji\AppData\Local\Programs\Python\Python38\lib\site-packages\uiautomator2\__init__.py", line 1395, in app_list_running
    self.shell('ps; ps -A').output, re.M)
  File "C:\Users\jiaji\AppData\Local\Programs\Python\Python38\lib\site-packages\uiautomator2\__init__.py", line 387, in shell
    ret = self.http.post("/shell", data=data, timeout=timeout+10)
  File "C:\Users\jiaji\AppData\Local\Programs\Python\Python38\lib\site-packages\requests\sessions.py", line 578, in post
    return self.request('POST', url, data=data, json=json, **kwargs)
  File "C:\Users\jiaji\AppData\Local\Programs\Python\Python38\lib\site-packages\uiautomator2\__init__.py", line 188, in request
    return super().request(method, url, **kwargs)
  File "C:\Users\jiaji\AppData\Local\Programs\Python\Python38\lib\site-packages\uiautomator2\__init__.py", line 108, in request
    resp = super(TimeoutRequestsSession,
  File "C:\Users\jiaji\AppData\Local\Programs\Python\Python38\lib\site-packages\requests\sessions.py", line 530, in request
    resp = self.send(prep, **send_kwargs)
  File "C:\Users\jiaji\AppData\Local\Programs\Python\Python38\lib\site-packages\requests\sessions.py", line 643, in send
    r = adapter.send(request, **kwargs)
  File "C:\Users\jiaji\AppData\Local\Programs\Python\Python38\lib\site-packages\requests\adapters.py", line 498, in send
    raise ConnectionError(err, request=request)
requests.exceptions.ConnectionError: ('Connection aborted.', RemoteDisconnected('Remote end closed connection without response'))
2020/09/21 20:42:27 - INFO - 44 - __init__ - ********开始 今日头条极速版 的任务********
2020/09/21 20:42:36 - INFO - 19 - jin_ri_tou_tiao - 开始签到
2020/09/21 20:42:44 - INFO - 164 - jin_ri_tou_tiao - 获取今日金币数量
2020/09/21 20:42:52 - INFO - 173 - jin_ri_tou_tiao - 今日已经获取金币 2453
2020/09/21 20:42:52 - INFO - 56 - jin_ri_tou_tiao - 开始阅读文章
2020/09/21 21:00:26 - INFO - 44 - __init__ - ********开始 今日头条极速版 的任务********
2020/09/21 21:00:33 - INFO - 19 - jin_ri_tou_tiao - 开始签到
2020/09/21 21:00:45 - INFO - 164 - jin_ri_tou_tiao - 获取今日金币数量
2020/09/21 21:00:52 - INFO - 173 - jin_ri_tou_tiao - 今日已经获取金币 5329
2020/09/21 21:00:52 - INFO - 56 - jin_ri_tou_tiao - 开始阅读文章
2020/09/21 21:00:26 - INFO - 44 - __init__ - ********开始 今日头条极速版 的任务********
2020/09/21 21:00:33 - INFO - 19 - jin_ri_tou_tiao - 开始签到
2020/09/21 21:00:45 - INFO - 164 - jin_ri_tou_tiao - 获取今日金币数量
2020/09/21 21:00:52 - INFO - 173 - jin_ri_tou_tiao - 今日已经获取金币 5329
2020/09/21 21:00:52 - INFO - 56 - jin_ri_tou_tiao - 开始阅读文章
2020/09/24 08:39:33 - INFO - 44 - __init__ - ********开始 彩蛋视频 的任务********
2020/09/24 08:39:41 - INFO - 91 - cai_dan - 获取今日金币数量
2020/09/24 08:39:47 - INFO - 106 - cai_dan - 今日已经获取金币 0
2020/09/24 08:39:47 - INFO - 61 - cai_dan - 开始阅读首页视频
2020/09/24 08:51:04 - INFO - 91 - cai_dan - 获取今日金币数量
2020/09/24 08:51:11 - INFO - 106 - cai_dan - 今日已经获取金币 504
2020/09/24 08:51:11 - INFO - 61 - cai_dan - 开始阅读首页视频
2020/09/24 09:02:20 - INFO - 91 - cai_dan - 获取今日金币数量
2020/09/24 09:02:28 - INFO - 106 - cai_dan - 今日已经获取金币 1046
2020/09/24 09:02:28 - INFO - 61 - cai_dan - 开始阅读首页视频
2020/09/24 09:13:33 - INFO - 91 - cai_dan - 获取今日金币数量
2020/09/24 09:13:38 - INFO - 106 - cai_dan - 今日已经获取金币 1588
2020/09/24 09:13:38 - INFO - 61 - cai_dan - 开始阅读首页视频
2020/09/24 09:14:02 - CRITICAL - 114 - __init__ - 出严重错误啦，以下是错误信息-32002 Client error: <> data: Selector [resourceId='com.jifen.dandan:id/lottie_view_gold'], method: None
Traceback (most recent call last):
  File "F:\python_project\read_phone_project\app_jiao_ben\__init__.py", line 109, in recycle_main_do
    self.main_do(duration, target_coin, cash_out)
  File "F:\python_project\read_phone_project\app_jiao_ben\cai_dan.py", line 140, in main_do
    self.pp(text='我').wait(timeout=30)
  File "F:\python_project\read_phone_project\app_jiao_ben\cai_dan.py", line 114, in read_issue
    while time.time() - issue_time_start <= duration and self.today_coin() <= target_coin:
  File "F:\python_project\read_phone_project\app_jiao_ben\cai_dan.py", line 65, in read_issue_first
    time.sleep(random.random() + 1)
  File "C:\Users\jiaji\AppData\Local\Programs\Python\Python38\lib\site-packages\uiautomator2\_selector.py", line 230, in drag_to
    self.must_wait(timeout=timeout)
  File "C:\Users\jiaji\AppData\Local\Programs\Python\Python38\lib\site-packages\uiautomator2\_selector.py", line 345, in must_wait
    raise UiObjectNotFoundError({'code': -32002, 'data': str(self.selector), 'method': 'wait'})
uiautomator2.exceptions.UiObjectNotFoundError: -32002 Client error: <> data: Selector [resourceId='com.jifen.dandan:id/lottie_view_gold'], method: None
2020/09/24 09:14:13 - INFO - 44 - __init__ - ********开始 彩蛋视频 的任务********
2020/09/24 09:14:26 - INFO - 91 - cai_dan - 获取今日金币数量
2020/09/24 09:14:34 - INFO - 106 - cai_dan - 今日已经获取金币 1588
2020/09/24 09:14:34 - INFO - 61 - cai_dan - 开始阅读首页视频
2020/09/24 09:25:53 - INFO - 91 - cai_dan - 获取今日金币数量
2020/09/24 09:26:01 - INFO - 106 - cai_dan - 今日已经获取金币 2130
2020/09/24 09:26:01 - INFO - 61 - cai_dan - 开始阅读首页视频
2020/09/24 09:37:31 - INFO - 91 - cai_dan - 获取今日金币数量
2020/09/24 09:37:41 - INFO - 106 - cai_dan - 今日已经获取金币 2672
2020/09/24 09:37:41 - INFO - 61 - cai_dan - 开始阅读首页视频
2020/09/24 09:49:01 - INFO - 91 - cai_dan - 获取今日金币数量
2020/09/24 09:49:06 - INFO - 106 - cai_dan - 今日已经获取金币 3276
2020/09/24 09:49:08 - INFO - 51 - __init__ - ********结束 彩蛋视频 APP 任务********
2020/09/24 09:49:31 - INFO - 44 - __init__ - ********开始 京东极速版 的任务********
2020/09/24 09:49:40 - INFO - 76 - jing_dong - 获取今日金币数量
2020/09/24 09:49:52 - INFO - 95 - jing_dong - 今日已经获取金币 41
2020/09/24 09:49:52 - INFO - 17 - jing_dong - 开始阅读首页视频
2020/09/24 09:56:44 - CRITICAL - 114 - __init__ - 出严重错误啦，以下是错误信息-32001 Jsonrpc error: <android.support.test.uiautomator.UiObjectNotFoundException> data: UiSelector[RESOURCE_ID=com.jd.lib.productdetail:id/title_back], method: objInfo
Traceback (most recent call last):
  File "F:\python_project\read_phone_project\app_jiao_ben\__init__.py", line 109, in recycle_main_do
    self.main_do(duration, target_coin, cash_out)
  File "F:\python_project\read_phone_project\app_jiao_ben\jing_dong.py", line 125, in main_do
    self.read_issue(duration, target_coin)
  File "F:\python_project\read_phone_project\app_jiao_ben\jing_dong.py", line 102, in read_issue
    self.read_issue_first(read_issue_time1, read_issue_time2)
  File "F:\python_project\read_phone_project\app_jiao_ben\jing_dong.py", line 21, in read_issue_first
    self._read_adv(read_issue_time1, read_issue_time2)
  File "F:\python_project\read_phone_project\app_jiao_ben\jing_dong.py", line 65, in _read_adv
    self.pp(resourceId='com.jd.lib.productdetail:id/title_back') \
  File "C:\Users\jiaji\AppData\Local\Programs\Python\Python38\lib\site-packages\uiautomator2\_selector.py", line 151, in click
    x, y = self.center(offset=offset)
  File "C:\Users\jiaji\AppData\Local\Programs\Python\Python38\lib\site-packages\uiautomator2\_selector.py", line 178, in center
    lx, ly, rx, ry = self.bounds()
  File "C:\Users\jiaji\AppData\Local\Programs\Python\Python38\lib\site-packages\uiautomator2\_selector.py", line 165, in bounds
    info = self.info
  File "<decorator-gen-4>", line 2, in info
  File "C:\Users\jiaji\AppData\Local\Programs\Python\Python38\lib\site-packages\retry\api.py", line 73, in retry_decorator
    return __retry_internal(partial(f, *args, **kwargs), exceptions, tries, delay, max_delay, backoff, jitter,
  File "C:\Users\jiaji\AppData\Local\Programs\Python\Python38\lib\site-packages\retry\api.py", line 33, in __retry_internal
    return f()
  File "C:\Users\jiaji\AppData\Local\Programs\Python\Python38\lib\site-packages\uiautomator2\_selector.py", line 130, in info
    return self.jsonrpc.objInfo(self.selector)
  File "C:\Users\jiaji\AppData\Local\Programs\Python\Python38\lib\site-packages\uiautomator2\__init__.py", line 431, in __call__
    return self.server._jsonrpc_retry_call(self.method, params,
  File "C:\Users\jiaji\AppData\Local\Programs\Python\Python38\lib\site-packages\uiautomator2\__init__.py", line 438, in _jsonrpc_retry_call
    return self._jsonrpc_call(*args, **kwargs)
  File "C:\Users\jiaji\AppData\Local\Programs\Python\Python38\lib\site-packages\uiautomator2\__init__.py", line 510, in _jsonrpc_call
    raise err
uiautomator2.exceptions.UiObjectNotFoundError: -32001 Jsonrpc error: <android.support.test.uiautomator.UiObjectNotFoundException> data: UiSelector[RESOURCE_ID=com.jd.lib.productdetail:id/title_back], method: objInfo
2020/09/24 09:56:55 - INFO - 44 - __init__ - ********开始 京东极速版 的任务********
2020/09/24 09:56:59 - INFO - 76 - jing_dong - 获取今日金币数量
2020/09/24 09:57:12 - INFO - 95 - jing_dong - 今日已经获取金币 1392
2020/09/24 09:57:12 - INFO - 17 - jing_dong - 开始阅读首页视频
2020/09/24 10:15:51 - INFO - 76 - jing_dong - 获取今日金币数量
2020/09/24 10:16:01 - INFO - 95 - jing_dong - 今日已经获取金币 3597
2020/09/24 10:16:01 - INFO - 17 - jing_dong - 开始阅读首页视频
2020/09/24 10:27:15 - INFO - 76 - jing_dong - 获取今日金币数量
2020/09/24 10:27:26 - INFO - 95 - jing_dong - 今日已经获取金币 4893
2020/09/24 10:27:26 - INFO - 17 - jing_dong - 开始阅读首页视频
2020/09/24 10:41:04 - INFO - 76 - jing_dong - 获取今日金币数量
2020/09/24 10:41:15 - INFO - 95 - jing_dong - 今日已经获取金币 6613
2020/09/24 10:41:15 - INFO - 17 - jing_dong - 开始阅读首页视频
2020/09/24 10:52:03 - INFO - 76 - jing_dong - 获取今日金币数量
2020/09/24 10:52:13 - INFO - 95 - jing_dong - 今日已经获取金币 7693
2020/09/24 10:52:13 - INFO - 17 - jing_dong - 开始阅读首页视频
2020/09/24 11:02:32 - INFO - 105 - jing_dong - 开始清理缓存
2020/09/24 11:02:39 - INFO - 51 - __init__ - ********结束 京东极速版 APP 任务********
2020/09/24 11:03:03 - INFO - 44 - __init__ - ********开始 魔方看点 的任务********
2020/09/24 11:03:24 - INFO - 18 - mo_fang_kan_dian - 开始签到
2020/09/24 11:03:39 - INFO - 189 - mo_fang_kan_dian - 已经获取 68 金币
2020/09/24 11:03:39 - INFO - 54 - mo_fang_kan_dian - 开始阅读文章
2020/09/24 11:17:26 - INFO - 189 - mo_fang_kan_dian - 已经获取 668 金币
2020/09/24 11:17:26 - INFO - 168 - mo_fang_kan_dian - 已经阅读获得了 668 金币
2020/09/24 11:17:29 - INFO - 176 - mo_fang_kan_dian - 看完这个栏目了，换个栏目
2020/09/24 11:23:47 - INFO - 189 - mo_fang_kan_dian - 已经获取 968 金币
2020/09/24 11:23:47 - INFO - 168 - mo_fang_kan_dian - 已经阅读获得了 968 金币
2020/09/24 11:23:49 - INFO - 176 - mo_fang_kan_dian - 看完这个栏目了，换个栏目
2020/09/24 11:30:36 - INFO - 189 - mo_fang_kan_dian - 已经获取 1218 金币
2020/09/24 11:30:36 - INFO - 168 - mo_fang_kan_dian - 已经阅读获得了 1218 金币
2020/09/24 11:30:39 - INFO - 176 - mo_fang_kan_dian - 看完这个栏目了，换个栏目
2020/09/24 11:45:04 - INFO - 189 - mo_fang_kan_dian - 已经获取 1968 金币
2020/09/24 11:45:04 - INFO - 168 - mo_fang_kan_dian - 已经阅读获得了 1968 金币
2020/09/24 11:45:07 - INFO - 176 - mo_fang_kan_dian - 看完这个栏目了，换个栏目
2020/09/24 11:55:10 - INFO - 189 - mo_fang_kan_dian - 已经获取 2318 金币
2020/09/24 11:55:10 - INFO - 168 - mo_fang_kan_dian - 已经阅读获得了 2318 金币
2020/09/24 11:55:12 - INFO - 176 - mo_fang_kan_dian - 看完这个栏目了，换个栏目
2020/09/24 12:04:24 - INFO - 154 - mo_fang_kan_dian - 今日阅读时间超过了3600秒，不再阅读了
2020/09/24 12:04:26 - INFO - 51 - __init__ - ********结束 魔方看点 APP 任务********
2020/09/24 12:04:53 - INFO - 44 - __init__ - ********开始 刷宝 的任务********
2020/09/24 12:05:07 - INFO - 22 - shua_bao - 开始签到
2020/09/24 12:05:23 - INFO - 33 - shua_bao - 获取今日金币数量
2020/09/24 12:05:32 - INFO - 44 - shua_bao - 今日已经获取金币 0
2020/09/24 12:05:32 - INFO - 90 - shua_bao - 开始阅读首页视频
2020/09/24 12:12:05 - CRITICAL - 114 - __init__ - 出严重错误啦，以下是错误信息-32002 Client error: <> data: Selector [resourceId='com.jm.video:id/editComment'], method: None
Traceback (most recent call last):
  File "F:\python_project\read_phone_project\app_jiao_ben\__init__.py", line 109, in recycle_main_do
    self.main_do(duration, target_coin, cash_out)
  File "F:\python_project\read_phone_project\app_jiao_ben\shua_bao.py", line 111, in main_do
    self.read_issue(duration, target_coin)
  File "F:\python_project\read_phone_project\app_jiao_ben\shua_bao.py", line 104, in read_issue
    self.read_issue_first(read_issue_time)
  File "F:\python_project\read_phone_project\app_jiao_ben\shua_bao.py", line 98, in read_issue_first
    self._read_issue_core(read_issue_time)
  File "F:\python_project\read_phone_project\app_jiao_ben\shua_bao.py", line 78, in _read_issue_core
    self.pp(resourceId='com.jm.video:id/editComment').click(offset=(random.random(), random.random()))
  File "C:\Users\jiaji\AppData\Local\Programs\Python\Python38\lib\site-packages\uiautomator2\_selector.py", line 150, in click
    self.must_wait(timeout=timeout)
  File "C:\Users\jiaji\AppData\Local\Programs\Python\Python38\lib\site-packages\uiautomator2\_selector.py", line 345, in must_wait
    raise UiObjectNotFoundError({'code': -32002, 'data': str(self.selector), 'method': 'wait'})
uiautomator2.exceptions.UiObjectNotFoundError: -32002 Client error: <> data: Selector [resourceId='com.jm.video:id/editComment'], method: None
2020/09/24 12:12:28 - INFO - 44 - __init__ - ********开始 刷宝 的任务********
2020/09/24 12:12:44 - INFO - 22 - shua_bao - 开始签到
2020/09/24 12:13:03 - INFO - 33 - shua_bao - 获取今日金币数量
2020/09/24 12:13:11 - INFO - 44 - shua_bao - 今日已经获取金币 1541
2020/09/24 12:13:11 - INFO - 90 - shua_bao - 开始阅读首页视频
2020/09/24 12:18:05 - CRITICAL - 114 - __init__ - 出严重错误啦，以下是错误信息-32002 Client error: <> data: Selector [resourceId='com.jm.video:id/editComment'], method: None
Traceback (most recent call last):
  File "F:\python_project\read_phone_project\app_jiao_ben\__init__.py", line 109, in recycle_main_do
    self.main_do(duration, target_coin, cash_out)
  File "F:\python_project\read_phone_project\app_jiao_ben\shua_bao.py", line 111, in main_do
    self.read_issue(duration, target_coin)
  File "F:\python_project\read_phone_project\app_jiao_ben\shua_bao.py", line 104, in read_issue
    self.read_issue_first(read_issue_time)
  File "F:\python_project\read_phone_project\app_jiao_ben\shua_bao.py", line 98, in read_issue_first
    self._read_issue_core(read_issue_time)
  File "F:\python_project\read_phone_project\app_jiao_ben\shua_bao.py", line 78, in _read_issue_core
    self.pp(resourceId='com.jm.video:id/editComment').click(offset=(random.random(), random.random()))
  File "C:\Users\jiaji\AppData\Local\Programs\Python\Python38\lib\site-packages\uiautomator2\_selector.py", line 150, in click
    self.must_wait(timeout=timeout)
  File "C:\Users\jiaji\AppData\Local\Programs\Python\Python38\lib\site-packages\uiautomator2\_selector.py", line 345, in must_wait
    raise UiObjectNotFoundError({'code': -32002, 'data': str(self.selector), 'method': 'wait'})
uiautomator2.exceptions.UiObjectNotFoundError: -32002 Client error: <> data: Selector [resourceId='com.jm.video:id/editComment'], method: None
2020/09/24 12:18:25 - INFO - 44 - __init__ - ********开始 刷宝 的任务********
2020/09/24 12:18:40 - INFO - 22 - shua_bao - 开始签到
2020/09/24 12:18:57 - INFO - 33 - shua_bao - 获取今日金币数量
2020/09/24 12:19:04 - INFO - 44 - shua_bao - 今日已经获取金币 2231
2020/09/24 12:19:04 - INFO - 90 - shua_bao - 开始阅读首页视频
2020/09/24 12:24:53 - INFO - 33 - shua_bao - 获取今日金币数量
2020/09/24 12:24:58 - INFO - 44 - shua_bao - 今日已经获取金币 2961
2020/09/24 12:24:58 - INFO - 90 - shua_bao - 开始阅读首页视频
2020/09/24 12:26:49 - CRITICAL - 114 - __init__ - 出严重错误啦，以下是错误信息-32002 Client error: <> data: Selector [resourceId='com.jm.video:id/editComment'], method: None
Traceback (most recent call last):
  File "F:\python_project\read_phone_project\app_jiao_ben\__init__.py", line 109, in recycle_main_do
    self.main_do(duration, target_coin, cash_out)
  File "F:\python_project\read_phone_project\app_jiao_ben\shua_bao.py", line 111, in main_do
    self.read_issue(duration, target_coin)
  File "F:\python_project\read_phone_project\app_jiao_ben\shua_bao.py", line 104, in read_issue
    self.read_issue_first(read_issue_time)
  File "F:\python_project\read_phone_project\app_jiao_ben\shua_bao.py", line 98, in read_issue_first
    self._read_issue_core(read_issue_time)
  File "F:\python_project\read_phone_project\app_jiao_ben\shua_bao.py", line 78, in _read_issue_core
    self.pp(resourceId='com.jm.video:id/editComment').click(offset=(random.random(), random.random()))
  File "C:\Users\jiaji\AppData\Local\Programs\Python\Python38\lib\site-packages\uiautomator2\_selector.py", line 150, in click
    self.must_wait(timeout=timeout)
  File "C:\Users\jiaji\AppData\Local\Programs\Python\Python38\lib\site-packages\uiautomator2\_selector.py", line 345, in must_wait
    raise UiObjectNotFoundError({'code': -32002, 'data': str(self.selector), 'method': 'wait'})
uiautomator2.exceptions.UiObjectNotFoundError: -32002 Client error: <> data: Selector [resourceId='com.jm.video:id/editComment'], method: None
2020/09/24 12:27:07 - INFO - 44 - __init__ - ********开始 刷宝 的任务********
2020/09/24 12:27:23 - INFO - 22 - shua_bao - 开始签到
2020/09/24 12:27:39 - INFO - 33 - shua_bao - 获取今日金币数量
2020/09/24 12:27:45 - INFO - 44 - shua_bao - 今日已经获取金币 3267
2020/09/24 12:27:45 - INFO - 90 - shua_bao - 开始阅读首页视频
2020/09/24 12:32:11 - CRITICAL - 114 - __init__ - 出严重错误啦，以下是错误信息-32002 Client error: <> data: Selector [resourceId='com.jm.video:id/editComment'], method: None
Traceback (most recent call last):
  File "F:\python_project\read_phone_project\app_jiao_ben\__init__.py", line 109, in recycle_main_do
    self.main_do(duration, target_coin, cash_out)
  File "F:\python_project\read_phone_project\app_jiao_ben\shua_bao.py", line 111, in main_do
    self.read_issue(duration, target_coin)
  File "F:\python_project\read_phone_project\app_jiao_ben\shua_bao.py", line 104, in read_issue
    self.read_issue_first(read_issue_time)
  File "F:\python_project\read_phone_project\app_jiao_ben\shua_bao.py", line 98, in read_issue_first
    self._read_issue_core(read_issue_time)
  File "F:\python_project\read_phone_project\app_jiao_ben\shua_bao.py", line 78, in _read_issue_core
    self.pp(resourceId='com.jm.video:id/editComment').click(offset=(random.random(), random.random()))
  File "C:\Users\jiaji\AppData\Local\Programs\Python\Python38\lib\site-packages\uiautomator2\_selector.py", line 150, in click
    self.must_wait(timeout=timeout)
  File "C:\Users\jiaji\AppData\Local\Programs\Python\Python38\lib\site-packages\uiautomator2\_selector.py", line 345, in must_wait
    raise UiObjectNotFoundError({'code': -32002, 'data': str(self.selector), 'method': 'wait'})
uiautomator2.exceptions.UiObjectNotFoundError: -32002 Client error: <> data: Selector [resourceId='com.jm.video:id/editComment'], method: None
2020/09/24 12:32:30 - INFO - 44 - __init__ - ********开始 刷宝 的任务********
2020/09/24 12:32:44 - INFO - 22 - shua_bao - 开始签到
2020/09/24 12:33:03 - INFO - 33 - shua_bao - 获取今日金币数量
2020/09/24 12:33:09 - INFO - 44 - shua_bao - 今日已经获取金币 3725
2020/09/24 12:33:09 - INFO - 90 - shua_bao - 开始阅读首页视频
2020/09/24 12:40:35 - INFO - 33 - shua_bao - 获取今日金币数量
2020/09/24 12:40:40 - INFO - 44 - shua_bao - 今日已经获取金币 4636
2020/09/24 12:40:40 - INFO - 90 - shua_bao - 开始阅读首页视频
2020/09/24 12:43:35 - CRITICAL - 114 - __init__ - 出严重错误啦，以下是错误信息-32002 Client error: <> data: Selector [resourceId='com.jm.video:id/editComment'], method: None
Traceback (most recent call last):
  File "F:\python_project\read_phone_project\app_jiao_ben\__init__.py", line 109, in recycle_main_do
    self.main_do(duration, target_coin, cash_out)
  File "F:\python_project\read_phone_project\app_jiao_ben\shua_bao.py", line 111, in main_do
    self.read_issue(duration, target_coin)
  File "F:\python_project\read_phone_project\app_jiao_ben\shua_bao.py", line 104, in read_issue
    self.read_issue_first(read_issue_time)
  File "F:\python_project\read_phone_project\app_jiao_ben\shua_bao.py", line 98, in read_issue_first
    self._read_issue_core(read_issue_time)
  File "F:\python_project\read_phone_project\app_jiao_ben\shua_bao.py", line 78, in _read_issue_core
    self.pp(resourceId='com.jm.video:id/editComment').click(offset=(random.random(), random.random()))
  File "C:\Users\jiaji\AppData\Local\Programs\Python\Python38\lib\site-packages\uiautomator2\_selector.py", line 150, in click
    self.must_wait(timeout=timeout)
  File "C:\Users\jiaji\AppData\Local\Programs\Python\Python38\lib\site-packages\uiautomator2\_selector.py", line 345, in must_wait
    raise UiObjectNotFoundError({'code': -32002, 'data': str(self.selector), 'method': 'wait'})
uiautomator2.exceptions.UiObjectNotFoundError: -32002 Client error: <> data: Selector [resourceId='com.jm.video:id/editComment'], method: None
2020/09/24 12:43:51 - INFO - 44 - __init__ - ********开始 刷宝 的任务********
2020/09/24 12:44:04 - INFO - 22 - shua_bao - 开始签到
2020/09/24 12:44:21 - INFO - 33 - shua_bao - 获取今日金币数量
2020/09/24 12:44:29 - INFO - 44 - shua_bao - 今日已经获取金币 5030
2020/09/24 12:44:29 - INFO - 90 - shua_bao - 开始阅读首页视频
2020/09/24 12:50:10 - CRITICAL - 114 - __init__ - 出严重错误啦，以下是错误信息-32002 Client error: <> data: Selector [resourceId='com.jm.video:id/editComment'], method: None
Traceback (most recent call last):
  File "F:\python_project\read_phone_project\app_jiao_ben\__init__.py", line 109, in recycle_main_do
    self.main_do(duration, target_coin, cash_out)
  File "F:\python_project\read_phone_project\app_jiao_ben\shua_bao.py", line 111, in main_do
    self.read_issue(duration, target_coin)
  File "F:\python_project\read_phone_project\app_jiao_ben\shua_bao.py", line 104, in read_issue
    self.read_issue_first(read_issue_time)
  File "F:\python_project\read_phone_project\app_jiao_ben\shua_bao.py", line 98, in read_issue_first
    self._read_issue_core(read_issue_time)
  File "F:\python_project\read_phone_project\app_jiao_ben\shua_bao.py", line 78, in _read_issue_core
    self.pp(resourceId='com.jm.video:id/editComment').click(offset=(random.random(), random.random()))
  File "C:\Users\jiaji\AppData\Local\Programs\Python\Python38\lib\site-packages\uiautomator2\_selector.py", line 150, in click
    self.must_wait(timeout=timeout)
  File "C:\Users\jiaji\AppData\Local\Programs\Python\Python38\lib\site-packages\uiautomator2\_selector.py", line 345, in must_wait
    raise UiObjectNotFoundError({'code': -32002, 'data': str(self.selector), 'method': 'wait'})
uiautomator2.exceptions.UiObjectNotFoundError: -32002 Client error: <> data: Selector [resourceId='com.jm.video:id/editComment'], method: None
2020/09/24 12:50:27 - INFO - 44 - __init__ - ********开始 刷宝 的任务********
2020/09/24 12:50:41 - INFO - 22 - shua_bao - 开始签到
2020/09/24 12:50:56 - INFO - 33 - shua_bao - 获取今日金币数量
2020/09/24 12:51:02 - INFO - 44 - shua_bao - 今日已经获取金币 5524
2020/09/24 12:51:02 - INFO - 90 - shua_bao - 开始阅读首页视频
2020/09/24 12:55:53 - CRITICAL - 114 - __init__ - 出严重错误啦，以下是错误信息-32002 Client error: <> data: Selector [resourceId='com.jm.video:id/editComment'], method: None
Traceback (most recent call last):
  File "F:\python_project\read_phone_project\app_jiao_ben\__init__.py", line 109, in recycle_main_do
    self.main_do(duration, target_coin, cash_out)
  File "F:\python_project\read_phone_project\app_jiao_ben\shua_bao.py", line 111, in main_do
    self.read_issue(duration, target_coin)
  File "F:\python_project\read_phone_project\app_jiao_ben\shua_bao.py", line 104, in read_issue
    self.read_issue_first(read_issue_time)
  File "F:\python_project\read_phone_project\app_jiao_ben\shua_bao.py", line 98, in read_issue_first
    self._read_issue_core(read_issue_time)
  File "F:\python_project\read_phone_project\app_jiao_ben\shua_bao.py", line 78, in _read_issue_core
    self.pp(resourceId='com.jm.video:id/editComment').click(offset=(random.random(), random.random()))
  File "C:\Users\jiaji\AppData\Local\Programs\Python\Python38\lib\site-packages\uiautomator2\_selector.py", line 150, in click
    self.must_wait(timeout=timeout)
  File "C:\Users\jiaji\AppData\Local\Programs\Python\Python38\lib\site-packages\uiautomator2\_selector.py", line 345, in must_wait
    raise UiObjectNotFoundError({'code': -32002, 'data': str(self.selector), 'method': 'wait'})
uiautomator2.exceptions.UiObjectNotFoundError: -32002 Client error: <> data: Selector [resourceId='com.jm.video:id/editComment'], method: None
2020/09/24 12:56:03 - INFO - 44 - __init__ - ********开始 刷宝 的任务********
2020/09/24 12:56:18 - INFO - 22 - shua_bao - 开始签到
2020/09/24 12:56:33 - INFO - 33 - shua_bao - 获取今日金币数量
2020/09/24 12:56:39 - INFO - 44 - shua_bao - 今日已经获取金币 6009
2020/09/24 12:56:39 - INFO - 48 - shua_bao - 开始清理缓存
2020/09/24 12:56:45 - INFO - 51 - __init__ - ********结束 刷宝 APP 任务********
2020/09/24 12:57:27 - INFO - 44 - __init__ - ********开始 惠头条 的任务********
2020/09/24 12:57:54 - INFO - 19 - hui_tou_tiao - 开始签到
2020/09/24 12:58:07 - CRITICAL - 114 - __init__ - 出严重错误啦，以下是错误信息-32001 Jsonrpc error: <android.support.test.uiautomator.UiObjectNotFoundException> data: UiSelector[TEXT=兑换提现], method: objInfo
Traceback (most recent call last):
  File "F:\python_project\read_phone_project\app_jiao_ben\__init__.py", line 109, in recycle_main_do
    self.main_do(duration, target_coin, cash_out)
  File "F:\python_project\read_phone_project\app_jiao_ben\hui_tou_tiao.py", line 234, in main_do
    if self.today_coin() < target_coin:
  File "F:\python_project\read_phone_project\app_jiao_ben\hui_tou_tiao.py", line 194, in today_coin
    self.pp(text='兑换提现').click(offset=(random.random(), random.random()))
  File "C:\Users\jiaji\AppData\Local\Programs\Python\Python38\lib\site-packages\uiautomator2\_selector.py", line 151, in click
    x, y = self.center(offset=offset)
  File "C:\Users\jiaji\AppData\Local\Programs\Python\Python38\lib\site-packages\uiautomator2\_selector.py", line 178, in center
    lx, ly, rx, ry = self.bounds()
  File "C:\Users\jiaji\AppData\Local\Programs\Python\Python38\lib\site-packages\uiautomator2\_selector.py", line 165, in bounds
    info = self.info
  File "<decorator-gen-4>", line 2, in info
  File "C:\Users\jiaji\AppData\Local\Programs\Python\Python38\lib\site-packages\retry\api.py", line 73, in retry_decorator
    return __retry_internal(partial(f, *args, **kwargs), exceptions, tries, delay, max_delay, backoff, jitter,
  File "C:\Users\jiaji\AppData\Local\Programs\Python\Python38\lib\site-packages\retry\api.py", line 33, in __retry_internal
    return f()
  File "C:\Users\jiaji\AppData\Local\Programs\Python\Python38\lib\site-packages\uiautomator2\_selector.py", line 130, in info
    return self.jsonrpc.objInfo(self.selector)
  File "C:\Users\jiaji\AppData\Local\Programs\Python\Python38\lib\site-packages\uiautomator2\__init__.py", line 431, in __call__
    return self.server._jsonrpc_retry_call(self.method, params,
  File "C:\Users\jiaji\AppData\Local\Programs\Python\Python38\lib\site-packages\uiautomator2\__init__.py", line 438, in _jsonrpc_retry_call
    return self._jsonrpc_call(*args, **kwargs)
  File "C:\Users\jiaji\AppData\Local\Programs\Python\Python38\lib\site-packages\uiautomator2\__init__.py", line 510, in _jsonrpc_call
    raise err
uiautomator2.exceptions.UiObjectNotFoundError: -32001 Jsonrpc error: <android.support.test.uiautomator.UiObjectNotFoundException> data: UiSelector[TEXT=兑换提现], method: objInfo
2020/09/24 12:58:17 - INFO - 44 - __init__ - ********开始 惠头条 的任务********
2020/09/24 12:58:44 - INFO - 19 - hui_tou_tiao - 开始签到
2020/09/24 12:59:02 - INFO - 201 - hui_tou_tiao - 已经获取 5760 金币
2020/09/24 12:59:02 - INFO - 237 - hui_tou_tiao - 今日已经获取超过目标金币，不再阅读了
2020/09/24 12:59:02 - INFO - 175 - hui_tou_tiao - 开始清理缓存
2020/09/24 12:59:17 - INFO - 51 - __init__ - ********结束 惠头条 APP 任务********
2020/09/24 12:59:47 - INFO - 44 - __init__ - ********开始 趣头条 的任务********
2020/09/24 13:00:25 - INFO - 20 - qu_tou_tiao - 获取今日金币数量
2020/09/24 13:00:37 - INFO - 25 - qu_tou_tiao - 今日获取 0 金币
2020/09/24 13:00:37 - INFO - 29 - qu_tou_tiao - 开始签到
2020/09/24 13:00:38 - INFO - 59 - qu_tou_tiao - 开始阅读文章
2020/09/24 13:00:47 - CRITICAL - 114 - __init__ - 出严重错误啦，以下是错误信息list index out of range
Traceback (most recent call last):
  File "F:\python_project\read_phone_project\app_jiao_ben\__init__.py", line 109, in recycle_main_do
    self.main_do(duration, target_coin, cash_out)
  File "F:\python_project\read_phone_project\app_jiao_ben\qu_tou_tiao.py", line 259, in main_do
    self.read_issue(duration, target_coin)
  File "F:\python_project\read_phone_project\app_jiao_ben\qu_tou_tiao.py", line 61, in read_issue
    self.pp.xpath('//*[@resource-id="com.jifen.qukan:id/n9"]/android.widget.FrameLayout[1]').wait()
  File "C:\Users\jiaji\AppData\Local\Programs\Python\Python38\lib\site-packages\uiautomator2\xpath.py", line 545, in wait
    return self.get_last_match()
  File "C:\Users\jiaji\AppData\Local\Programs\Python\Python38\lib\site-packages\uiautomator2\xpath.py", line 513, in get_last_match
    return self.all(self._last_source)[0]
IndexError: list index out of range
2020/09/24 13:00:57 - INFO - 44 - __init__ - ********开始 趣头条 的任务********
2020/09/24 13:01:28 - INFO - 20 - qu_tou_tiao - 获取今日金币数量
2020/09/24 13:01:40 - INFO - 25 - qu_tou_tiao - 今日获取 308 金币
2020/09/24 13:01:40 - INFO - 29 - qu_tou_tiao - 开始签到
2020/09/24 13:01:41 - INFO - 59 - qu_tou_tiao - 开始阅读文章
2020/09/24 13:18:25 - INFO - 20 - qu_tou_tiao - 获取今日金币数量
2020/09/24 13:18:34 - INFO - 25 - qu_tou_tiao - 今日获取 1496 金币
2020/09/24 13:18:37 - INFO - 155 - qu_tou_tiao - 看完这个栏目了，换个栏目
2020/09/24 13:37:37 - INFO - 20 - qu_tou_tiao - 获取今日金币数量
2020/09/24 13:37:46 - INFO - 25 - qu_tou_tiao - 今日获取 2372 金币
2020/09/24 13:37:49 - INFO - 155 - qu_tou_tiao - 看完这个栏目了，换个栏目
2020/09/24 13:55:47 - INFO - 20 - qu_tou_tiao - 获取今日金币数量
2020/09/24 13:56:29 - CRITICAL - 114 - __init__ - 出严重错误啦，以下是错误信息-32002 Client error: <> data: Selector [text='我的'], method: None
Traceback (most recent call last):
  File "F:\python_project\read_phone_project\app_jiao_ben\__init__.py", line 109, in recycle_main_do
    self.main_do(duration, target_coin, cash_out)
  File "F:\python_project\read_phone_project\app_jiao_ben\qu_tou_tiao.py", line 259, in main_do
    self.read_issue(duration, target_coin)
  File "F:\python_project\read_phone_project\app_jiao_ben\qu_tou_tiao.py", line 147, in read_issue
    coin = self.today_coin()
  File "F:\python_project\read_phone_project\app_jiao_ben\qu_tou_tiao.py", line 22, in today_coin
    self.pp(text='我的').click(offset=(random.random(), random.random()))
  File "C:\Users\jiaji\AppData\Local\Programs\Python\Python38\lib\site-packages\uiautomator2\_selector.py", line 150, in click
    self.must_wait(timeout=timeout)
  File "C:\Users\jiaji\AppData\Local\Programs\Python\Python38\lib\site-packages\uiautomator2\_selector.py", line 345, in must_wait
    raise UiObjectNotFoundError({'code': -32002, 'data': str(self.selector), 'method': 'wait'})
uiautomator2.exceptions.UiObjectNotFoundError: -32002 Client error: <> data: Selector [text='我的'], method: None
2020/09/24 13:56:50 - INFO - 44 - __init__ - ********开始 趣头条 的任务********
2020/09/24 13:57:28 - INFO - 20 - qu_tou_tiao - 获取今日金币数量
2020/09/24 13:57:41 - INFO - 25 - qu_tou_tiao - 今日获取 3194 金币
2020/09/24 13:57:41 - INFO - 29 - qu_tou_tiao - 开始签到
2020/09/24 13:57:42 - INFO - 59 - qu_tou_tiao - 开始阅读文章
2020/09/24 14:01:40 - INFO - 20 - qu_tou_tiao - 获取今日金币数量
2020/09/24 14:02:22 - CRITICAL - 114 - __init__ - 出严重错误啦，以下是错误信息-32002 Client error: <> data: Selector [text='我的'], method: None
Traceback (most recent call last):
  File "F:\python_project\read_phone_project\app_jiao_ben\__init__.py", line 109, in recycle_main_do
    self.main_do(duration, target_coin, cash_out)
  File "F:\python_project\read_phone_project\app_jiao_ben\qu_tou_tiao.py", line 259, in main_do
    self.read_issue(duration, target_coin)
  File "F:\python_project\read_phone_project\app_jiao_ben\qu_tou_tiao.py", line 147, in read_issue
    coin = self.today_coin()
  File "F:\python_project\read_phone_project\app_jiao_ben\qu_tou_tiao.py", line 22, in today_coin
    self.pp(text='我的').click(offset=(random.random(), random.random()))
  File "C:\Users\jiaji\AppData\Local\Programs\Python\Python38\lib\site-packages\uiautomator2\_selector.py", line 150, in click
    self.must_wait(timeout=timeout)
  File "C:\Users\jiaji\AppData\Local\Programs\Python\Python38\lib\site-packages\uiautomator2\_selector.py", line 345, in must_wait
    raise UiObjectNotFoundError({'code': -32002, 'data': str(self.selector), 'method': 'wait'})
uiautomator2.exceptions.UiObjectNotFoundError: -32002 Client error: <> data: Selector [text='我的'], method: None
2020/09/24 14:02:23 - CRITICAL - 119 - __init__ - 程序存在错误，试了一个小时都不行，请修改程序
2020/09/24 14:02:28 - INFO - 51 - __init__ - ********结束 趣头条 APP 任务********
2020/09/24 14:02:57 - INFO - 44 - __init__ - ********开始 快手极速版 的任务********
2020/09/24 14:03:27 - INFO - 17 - kuai_shou - 开始签到
2020/09/24 14:03:59 - INFO - 30 - kuai_shou - 获取今日金币数量
2020/09/24 14:04:23 - INFO - 46 - kuai_shou - 今日已经获取金币 18
2020/09/24 14:04:23 - INFO - 100 - kuai_shou - 开始阅读发现视频
2020/09/24 14:15:51 - INFO - 30 - kuai_shou - 获取今日金币数量
2020/09/24 14:16:09 - INFO - 46 - kuai_shou - 今日已经获取金币 1560
2020/09/24 14:16:09 - INFO - 110 - kuai_shou - 开始阅读同城视频
2020/09/24 14:17:03 - INFO - 30 - kuai_shou - 获取今日金币数量
2020/09/24 14:17:18 - INFO - 46 - kuai_shou - 今日已经获取金币 1887
2020/09/24 14:17:18 - INFO - 100 - kuai_shou - 开始阅读发现视频
2020/09/24 14:28:44 - INFO - 30 - kuai_shou - 获取今日金币数量
2020/09/24 14:29:01 - INFO - 46 - kuai_shou - 今日已经获取金币 2748
2020/09/24 14:29:01 - INFO - 110 - kuai_shou - 开始阅读同城视频
2020/09/24 14:29:54 - INFO - 30 - kuai_shou - 获取今日金币数量
2020/09/24 14:30:11 - INFO - 46 - kuai_shou - 今日已经获取金币 2807
2020/09/24 14:30:11 - INFO - 100 - kuai_shou - 开始阅读发现视频
2020/09/24 14:41:37 - INFO - 30 - kuai_shou - 获取今日金币数量
2020/09/24 14:41:54 - INFO - 46 - kuai_shou - 今日已经获取金币 3642
2020/09/24 14:41:54 - INFO - 110 - kuai_shou - 开始阅读同城视频
2020/09/24 14:42:48 - INFO - 30 - kuai_shou - 获取今日金币数量
2020/09/24 14:43:41 - CRITICAL - 114 - __init__ - 出严重错误啦，以下是错误信息['//*[@resource-id="com.kuaishou.nebula:id/webView"]/android.webkit.WebView[1]/android.webkit.WebView[1]/android.widget.ListView[1]/android.view.View[1]/android.view.View[1]']
Traceback (most recent call last):
  File "F:\python_project\read_phone_project\app_jiao_ben\__init__.py", line 109, in recycle_main_do
    self.main_do(duration, target_coin, cash_out)
  File "F:\python_project\read_phone_project\app_jiao_ben\kuai_shou.py", line 143, in main_do
    self.read_issue(duration, target_coin)
  File "F:\python_project\read_phone_project\app_jiao_ben\kuai_shou.py", line 132, in read_issue
    while time.time() - issue_time_start <= duration and self.today_coin() <= target_coin:
  File "F:\python_project\read_phone_project\app_jiao_ben\kuai_shou.py", line 36, in today_coin
    coin = self.pp.xpath('//*[@resource-id="com.kuaishou.nebula:id/webView"]/android.webkit.WebView[1]/'
  File "C:\Users\jiaji\AppData\Local\Programs\Python\Python38\lib\site-packages\uiautomator2\xpath.py", line 509, in get
    raise XPathElementNotFoundError(self._xpath_list)
uiautomator2.exceptions.XPathElementNotFoundError: ['//*[@resource-id="com.kuaishou.nebula:id/webView"]/android.webkit.WebView[1]/android.webkit.WebView[1]/android.widget.ListView[1]/android.view.View[1]/android.view.View[1]']
2020/09/24 14:43:57 - INFO - 44 - __init__ - ********开始 快手极速版 的任务********
2020/09/24 14:44:17 - INFO - 17 - kuai_shou - 开始签到
2020/09/24 14:44:40 - INFO - 30 - kuai_shou - 获取今日金币数量
2020/09/24 14:44:56 - INFO - 46 - kuai_shou - 今日已经获取金币 3797
2020/09/24 14:44:56 - INFO - 100 - kuai_shou - 开始阅读发现视频
2020/09/24 14:58:31 - INFO - 30 - kuai_shou - 获取今日金币数量
2020/09/24 14:58:47 - INFO - 46 - kuai_shou - 今日已经获取金币 5290
2020/09/24 14:58:47 - INFO - 110 - kuai_shou - 开始阅读同城视频
2020/09/24 14:59:57 - INFO - 30 - kuai_shou - 获取今日金币数量
2020/09/24 15:00:15 - INFO - 46 - kuai_shou - 今日已经获取金币 5396
2020/09/24 15:00:15 - INFO - 100 - kuai_shou - 开始阅读发现视频
2020/09/24 15:13:51 - INFO - 30 - kuai_shou - 获取今日金币数量
2020/09/24 15:14:10 - INFO - 46 - kuai_shou - 今日已经获取金币 6404
2020/09/24 15:14:10 - INFO - 50 - kuai_shou - 开始清理缓存
2020/09/24 15:14:18 - INFO - 51 - __init__ - ********结束 快手极速版 APP 任务********
2020/09/24 15:14:45 - INFO - 44 - __init__ - ********开始 闪电盒子 的任务********
2020/09/24 15:15:15 - INFO - 18 - shan_dian_he_zi - 开始签到
2020/09/24 15:15:57 - CRITICAL - 114 - __init__ - 出严重错误啦，以下是错误信息-32002 Client error: <> data: Selector [text='任务'], method: None
Traceback (most recent call last):
  File "F:\python_project\read_phone_project\app_jiao_ben\__init__.py", line 109, in recycle_main_do
    self.main_do(duration, target_coin, cash_out)
  File "F:\python_project\read_phone_project\app_jiao_ben\shan_dian_he_zi.py", line 177, in main_do
    self.sign_in()
  File "F:\python_project\read_phone_project\app_jiao_ben\shan_dian_he_zi.py", line 20, in sign_in
    self.pp(text='任务').click(offset=(random.random(), random.random()))
  File "C:\Users\jiaji\AppData\Local\Programs\Python\Python38\lib\site-packages\uiautomator2\_selector.py", line 150, in click
    self.must_wait(timeout=timeout)
  File "C:\Users\jiaji\AppData\Local\Programs\Python\Python38\lib\site-packages\uiautomator2\_selector.py", line 345, in must_wait
    raise UiObjectNotFoundError({'code': -32002, 'data': str(self.selector), 'method': 'wait'})
uiautomator2.exceptions.UiObjectNotFoundError: -32002 Client error: <> data: Selector [text='任务'], method: None
2020/09/24 15:16:05 - INFO - 44 - __init__ - ********开始 闪电盒子 的任务********
2020/09/24 15:16:24 - INFO - 18 - shan_dian_he_zi - 开始签到
2020/09/24 15:16:27 - INFO - 109 - shan_dian_he_zi - 开始阅读文章
2020/09/24 15:16:31 - CRITICAL - 114 - __init__ - 出严重错误啦，以下是错误信息list index out of range
Traceback (most recent call last):
  File "F:\python_project\read_phone_project\app_jiao_ben\__init__.py", line 109, in recycle_main_do
    self.main_do(duration, target_coin, cash_out)
  File "F:\python_project\read_phone_project\app_jiao_ben\shan_dian_he_zi.py", line 178, in main_do
    self.read_issue(duration, target_coin)
  File "F:\python_project\read_phone_project\app_jiao_ben\shan_dian_he_zi.py", line 111, in read_issue
    self.pp.xpath('//*[@resource-id="c.l.a:id/bottom_navigation"]/android.widget.RelativeLayout[1]/'
  File "C:\Users\jiaji\AppData\Local\Programs\Python\Python38\lib\site-packages\uiautomator2\xpath.py", line 545, in wait
    return self.get_last_match()
  File "C:\Users\jiaji\AppData\Local\Programs\Python\Python38\lib\site-packages\uiautomator2\xpath.py", line 513, in get_last_match
    return self.all(self._last_source)[0]
IndexError: list index out of range
2020/09/24 15:16:39 - INFO - 44 - __init__ - ********开始 闪电盒子 的任务********
2020/09/24 15:16:59 - INFO - 18 - shan_dian_he_zi - 开始签到
2020/09/24 15:17:05 - INFO - 109 - shan_dian_he_zi - 开始阅读文章
2020/09/24 15:17:14 - INFO - 135 - shan_dian_he_zi - 已经获取 56490 金币
2020/09/24 15:17:14 - INFO - 25 - shan_dian_he_zi - 开始阅读首页视频
2020/09/24 15:21:18 - INFO - 135 - shan_dian_he_zi - 已经获取 64942 金币
2020/09/24 15:21:18 - INFO - 98 - shan_dian_he_zi - 开始阅读同城视频
2020/09/24 15:26:58 - INFO - 135 - shan_dian_he_zi - 已经获取 67998 金币
2020/09/24 15:26:58 - INFO - 25 - shan_dian_he_zi - 开始阅读首页视频
2020/09/24 15:28:03 - INFO - 135 - shan_dian_he_zi - 已经获取 70942 金币
2020/09/24 15:28:03 - INFO - 98 - shan_dian_he_zi - 开始阅读同城视频
2020/09/24 15:33:43 - INFO - 135 - shan_dian_he_zi - 已经获取 73652 金币
2020/09/24 15:33:43 - INFO - 25 - shan_dian_he_zi - 开始阅读首页视频
2020/09/24 15:35:34 - INFO - 135 - shan_dian_he_zi - 已经获取 76893 金币
2020/09/24 15:35:34 - INFO - 98 - shan_dian_he_zi - 开始阅读同城视频
2020/09/24 15:41:12 - INFO - 135 - shan_dian_he_zi - 已经获取 78788 金币
2020/09/24 15:41:12 - INFO - 25 - shan_dian_he_zi - 开始阅读首页视频
2020/09/24 15:43:12 - INFO - 135 - shan_dian_he_zi - 已经获取 81382 金币
2020/09/24 15:43:23 - INFO - 51 - __init__ - ********结束 闪电盒子 APP 任务********
2020/09/24 15:43:49 - INFO - 44 - __init__ - ********开始 火山极速版 的任务********
2020/09/24 15:44:05 - INFO - 119 - huo_shan - 开始签到
2020/09/24 15:44:14 - INFO - 74 - huo_shan - 获取今日金币数量
2020/09/24 15:44:21 - INFO - 86 - huo_shan - 今日已经获取金币 0
2020/09/24 15:44:21 - INFO - 50 - huo_shan - 开始阅读首页视频
2020/09/24 15:56:52 - INFO - 74 - huo_shan - 获取今日金币数量
2020/09/24 15:56:59 - INFO - 86 - huo_shan - 今日已经获取金币 0
2020/09/24 15:56:59 - INFO - 58 - huo_shan - 开始阅读推荐视频
2020/09/24 16:05:08 - INFO - 74 - huo_shan - 获取今日金币数量
2020/09/24 16:05:13 - INFO - 86 - huo_shan - 今日已经获取金币 876
2020/09/24 16:05:13 - INFO - 50 - huo_shan - 开始阅读首页视频
2020/09/24 16:17:40 - INFO - 74 - huo_shan - 获取今日金币数量
2020/09/24 16:17:46 - INFO - 86 - huo_shan - 今日已经获取金币 876
2020/09/24 16:17:46 - INFO - 58 - huo_shan - 开始阅读推荐视频
